<?xml version="1.0" encoding="utf-8"?>
<robot xmlns:xacro="http://www.ros.org/wiki/xacro" name="audix">
  <xacro:arg name="controllers_yaml" default=""/>

  <!-- ============================================================ -->
  <!-- BASE LINK                                                     -->
  <!-- ============================================================ -->
  <link name="base_link">
    <inertial>
      <origin xyz="-0.16542560919261 -0.149974396919816 0.0555112241124055" rpy="0 0 0"/>
      <mass value="2.23789814285683"/>
      <inertia ixx="0.0100668608395496" ixy="3.41741618462473E-05" ixz="8.32772399082271E-05"
               iyy="0.0114849385643874" iyz="8.93952677484501E-05" izz="0.0190387521155491"/>
    </inertial>
    <visual>
      <origin xyz="0 0 0" rpy="0 0 0"/>
      <geometry><mesh filename="package://audix/meshes/base_link.STL"/></geometry>
      <material name=""><color rgba="0.792 0.820 0.933 1"/></material>
    </visual>
    <!-- dartsim does not support mesh collision — use box approximation -->
    <collision>
      <origin xyz="-0.165 -0.150 0.055" rpy="0 0 0"/>
      <geometry><box size="0.32 0.35 0.11"/></geometry>
    </collision>
  </link>

  <!-- RobotBody frame — used as base_frame_id in controllers/EKF -->
  <link name="RobotBody"/>
  <joint name="robot_body_joint" type="fixed">
    <origin xyz="0 0 0" rpy="0 0 3.14159"/>
    <parent link="base_link"/>
    <child link="RobotBody"/>
  </joint>

  <!-- ============================================================ -->
  <!-- WHEELS                                                        -->
  <!-- ============================================================ -->
  <link name="front_left_wheel_link">
    <inertial>
      <origin xyz="2.171E-06 2.032E-07 -0.005531" rpy="0 0 0"/>
      <mass value="0.131907"/>
      <inertia ixx="2.276E-05" ixy="-1.026E-09" ixz="1.976E-10"
               iyy="2.277E-05" iyz="-1.733E-09" izz="2.867E-05"/>
    </inertial>
    <visual>
      <origin xyz="0 0 0" rpy="0 0 0"/>
      <geometry><mesh filename="package://audix/meshes/front_left_wheel_link.STL"/></geometry>
      <material name=""><color rgba="0.792 0.820 0.933 1"/></material>
    </visual>
    <collision>
      <origin xyz="0 0 0" rpy="0 0 0"/>
      <geometry><cylinder radius="0.0485" length="0.025"/></geometry>
    </collision>
  </link>
  <joint name="front_left_wheel_joint" type="continuous">
    <origin xyz="-0.250000000005374 -0.307389999999985 0.024999999989585" rpy="1.57079632679489 0 0"/>
    <parent link="base_link"/>
    <child link="front_left_wheel_link"/>
    <axis xyz="0 0 -1"/>
  </joint>

  <link name="front_right_wheel_link">
    <inertial>
      <origin xyz="9.668E-07 -2.182E-06 0.005592" rpy="0 0 0"/>
      <mass value="0.131907"/>
      <inertia ixx="2.277E-05" ixy="3.235E-09" ixz="1.613E-09"
               iyy="2.276E-05" iyz="6.662E-10" izz="2.867E-05"/>
    </inertial>
    <visual>
      <origin xyz="0 0 0" rpy="0 0 0"/>
      <geometry><mesh filename="package://audix/meshes/front_right_wheel_link.STL"/></geometry>
      <material name=""><color rgba="0.792 0.820 0.933 1"/></material>
    </visual>
    <collision>
      <origin xyz="0 0 0" rpy="0 0 0"/>
      <geometry><cylinder radius="0.0485" length="0.025"/></geometry>
    </collision>
  </link>
  <joint name="front_right_wheel_joint" type="continuous">
    <origin xyz="-0.250000000005375 0.00739000000001477 0.0249999999895845" rpy="1.57079632679489 0 0"/>
    <parent link="base_link"/>
    <child link="front_right_wheel_link"/>
    <axis xyz="0 0 -1"/>
  </joint>

  <link name="back_right_wheel_link">
    <inertial>
      <origin xyz="3.945E-07 -2.204E-06 0.005531" rpy="0 0 0"/>
      <mass value="0.131907"/>
      <inertia ixx="2.277E-05" ixy="1.749E-09" ixz="-1.701E-09"
               iyy="2.276E-05" iyz="-4.123E-10" izz="2.867E-05"/>
    </inertial>
    <visual>
      <origin xyz="0 0 0" rpy="0 0 0"/>
      <geometry><mesh filename="package://audix/meshes/back_right_wheel_link.STL"/></geometry>
      <material name=""><color rgba="0.792 0.820 0.933 1"/></material>
    </visual>
    <collision>
      <origin xyz="0 0 0" rpy="0 0 0"/>
      <geometry><cylinder radius="0.0485" length="0.025"/></geometry>
    </collision>
  </link>
  <joint name="back_right_wheel_joint" type="continuous">
    <origin xyz="-0.0700000000053771 0.00739000000001488 0.0249999999906142" rpy="1.57079632679489 0 0"/>
    <parent link="base_link"/>
    <child link="back_right_wheel_link"/>
    <axis xyz="0 0 -1"/>
  </joint>

  <link name="back_left_wheel_link">
    <inertial>
      <origin xyz="2.281E-06 3.552E-07 -0.005592" rpy="0 0 0"/>
      <mass value="0.131907"/>
      <inertia ixx="2.276E-05" ixy="-1.514E-09" ixz="-3.703E-10"
               iyy="2.277E-05" iyz="1.715E-09" izz="2.867E-05"/>
    </inertial>
    <visual>
      <origin xyz="0 0 0" rpy="0 0 0"/>
      <geometry><mesh filename="package://audix/meshes/back_left_wheel_link.STL"/></geometry>
      <material name=""><color rgba="0.792 0.820 0.933 1"/></material>
    </visual>
    <collision>
      <origin xyz="0 0 0" rpy="0 0 0"/>
      <geometry><cylinder radius="0.0485" length="0.025"/></geometry>
    </collision>
  </link>
  <joint name="back_left_wheel_joint" type="continuous">
    <origin xyz="-0.0700000000053768 -0.307389999999987 0.024999999990612" rpy="1.57079632679489 0 0"/>
    <parent link="base_link"/>
    <child link="back_left_wheel_link"/>
    <axis xyz="0 0 -1"/>
  </joint>

  <!-- ============================================================ -->
  <!-- SCISSOR LIFT                                                  -->
  <!-- ============================================================ -->
  <link name="scissors_lift_base">
    <inertial>
      <origin xyz="0.0640804372971069 6.00038746534359E-06 0.0414333132690798" rpy="0 0 0"/>
      <mass value="0.240484568977745"/>
      <inertia ixx="0.000179982875596582" ixy="-4.87618112557164E-08" ixz="-3.47904212839925E-05"
               iyy="0.000579348711169908" iyz="-5.93888337150469E-10" izz="0.000667789961401685"/>
    </inertial>
    <visual>
      <origin xyz="0 0 0" rpy="0 0 0"/>
      <geometry><mesh filename="package://audix/meshes/scissors_lift_base.STL"/></geometry>
      <material name=""><color rgba="0.792 0.820 0.933 1"/></material>
    </visual>
    <collision>
      <origin xyz="0.064 0.0 0.041" rpy="0 0 0"/>
      <geometry><box size="0.22 0.10 0.08"/></geometry>
    </collision>
  </link>
  <joint name="scissors_lift_base_fix" type="fixed">
    <origin xyz="-0.310000000005584 -0.150000000000003 0.0124999999899842" rpy="0 0 0"/>
    <parent link="base_link"/>
    <child link="scissors_lift_base"/>
  </joint>

  <!-- Bottom stud (lead screw carriage) — THE actuated prismatic joint -->
  <link name="bottom_stud_link">
    <inertial>
      <origin xyz="-9.66E-07 7.194E-07 -1.301E-06" rpy="0 0 0"/>
      <mass value="0.00137057"/>
      <inertia ixx="1.363E-06" ixy="8.795E-12" ixz="-3.233E-14"
               iyy="2.721E-09" iyz="-7.187E-12" izz="1.363E-06"/>
    </inertial>
    <visual>
      <origin xyz="0 0 0" rpy="0 0 0"/>
      <geometry><mesh filename="package://audix/meshes/bottom_stud_link.STL"/></geometry>
      <material name=""><color rgba="0.776 0.757 0.737 1"/></material>
    </visual>
    <collision>
      <origin xyz="0 0 0" rpy="0 0 0"/>
      <geometry><cylinder radius="0.004" length="0.015"/></geometry>
    </collision>
  </link>
  <joint name="bottom_stud_joint" type="prismatic">
    <origin xyz="0.137801664111862 -0.000349280592105594 0.0424989715630968" rpy="3.14159265358979 1.5707963267949 0"/>
    <parent link="scissors_lift_base"/>
    <child link="bottom_stud_link"/>
    <axis xyz="0 0 1"/>
    <limit lower="0.0" upper="0.0772" effort="150" velocity="0.05"/>
  </joint>

  <!-- Right side scissor links -->
  <link name="right_link1">
    <inertial>
      <origin xyz="0.0589 0.01143 0" rpy="0 0 0"/>
      <mass value="0.006154"/>
      <inertia ixx="3.585E-07" ixy="-1.513E-06" ixz="0" iyy="7.863E-06" iyz="0" izz="8.195E-06"/>
    </inertial>
    <visual><origin xyz="0 0 0" rpy="0 0 0"/><geometry><mesh filename="package://audix/meshes/right_link1.STL"/></geometry><material name=""><color rgba="0.792 0.820 0.933 1"/></material></visual>
    <collision><origin xyz="0.059 0.011 0.0" rpy="0 0 0"/><geometry><box size="0.12 0.015 0.012"/></geometry></collision>
  </link>
  <joint name="right_joint1" type="revolute">
    <origin xyz="0 -0.0428492805920998 0" rpy="1.5707963267949 -1.5707963267949 0"/>
    <parent link="bottom_stud_link"/><child link="right_link1"/>
    <axis xyz="0 0 1"/>
    <limit lower="-1.5708" upper="1.5708" effort="80" velocity="3.0"/>
  </joint>

  <link name="right_link4">
    <inertial><origin xyz="0.0589 0.01143 0" rpy="0 0 0"/><mass value="0.006154"/>
      <inertia ixx="3.585E-07" ixy="-1.513E-06" ixz="0" iyy="7.863E-06" iyz="0" izz="8.195E-06"/></inertial>
    <visual><origin xyz="0 0 0" rpy="0 0 0"/><geometry><mesh filename="package://audix/meshes/right_link4.STL"/></geometry><material name=""><color rgba="0.792 0.820 0.933 1"/></material></visual>
    <collision><origin xyz="0.059 0.011 0.0" rpy="0 0 0"/><geometry><box size="0.12 0.015 0.012"/></geometry></collision>
  </link>
  <joint name="right_joint4" type="revolute">
    <origin xyz="0.117803138552677 0.022856520888779 -0.00500000000000089" rpy="3.14159265358979 0 3.14159265358979"/>
    <parent link="right_link1"/><child link="right_link4"/>
    <axis xyz="0 0 1"/>
    <limit lower="-1.5708" upper="1.5708" effort="80" velocity="3.0"/>
  </joint>

  <link name="right_link5">
    <inertial><origin xyz="0.0589 0.01104 0.00297" rpy="0 0 0"/><mass value="0.006154"/>
      <inertia ixx="3.585E-07" ixy="-1.461E-06" ixz="-3.929E-07" iyy="7.885E-06" iyz="-8.347E-08" izz="8.173E-06"/></inertial>
    <visual><origin xyz="0 0 0" rpy="0 0 0"/><geometry><mesh filename="package://audix/meshes/right_link5.STL"/></geometry><material name=""><color rgba="0.792 0.820 0.933 1"/></material></visual>
    <collision><origin xyz="0.059 0.011 0.003" rpy="0 0 0"/><geometry><box size="0.12 0.015 0.012"/></geometry></collision>
  </link>
  <joint name="right_joint5" type="revolute">
    <origin xyz="0.117803138552938 0.0228565208873703 -0.00499999999999845" rpy="3.14159265358979 0 3.14159265358979"/>
    <parent link="right_link4"/><child link="right_link5"/>
    <axis xyz="0 0 -1"/>
    <limit lower="-1.5708" upper="1.5708" effort="80" velocity="3.0"/>
  </joint>

  <!-- Left side scissor links -->
  <link name="left_link1">
    <inertial><origin xyz="0.0589 0.01143 0" rpy="0 0 0"/><mass value="0.006154"/>
      <inertia ixx="3.585E-07" ixy="-1.513E-06" ixz="0" iyy="7.863E-06" iyz="0" izz="8.195E-06"/></inertial>
    <visual><origin xyz="0 0 0" rpy="0 0 0"/><geometry><mesh filename="package://audix/meshes/left_link1.STL"/></geometry><material name=""><color rgba="0.792 0.820 0.933 1"/></material></visual>
    <collision><origin xyz="0.059 0.011 0.0" rpy="0 0 0"/><geometry><box size="0.12 0.015 0.012"/></geometry></collision>
  </link>
  <joint name="left_joint1" type="revolute">
    <origin xyz="0 0.0421507194079047 0" rpy="1.5707963267949 -1.5707963267949 0"/>
    <parent link="bottom_stud_link"/><child link="left_link1"/>
    <axis xyz="0 0 1"/>
    <limit lower="-1.5708" upper="1.5708" effort="80" velocity="3.0"/>
  </joint>

  <link name="left_link4">
    <inertial><origin xyz="0.0589 0.01143 0" rpy="0 0 0"/><mass value="0.006154"/>
      <inertia ixx="3.585E-07" ixy="-1.513E-06" ixz="0" iyy="7.863E-06" iyz="0" izz="8.195E-06"/></inertial>
    <visual><origin xyz="0 0 0" rpy="0 0 0"/><geometry><mesh filename="package://audix/meshes/left_link4.STL"/></geometry><material name=""><color rgba="0.792 0.820 0.933 1"/></material></visual>
    <collision><origin xyz="0.059 0.011 0.0" rpy="0 0 0"/><geometry><box size="0.12 0.015 0.012"/></geometry></collision>
  </link>
  <joint name="left_joint4" type="revolute">
    <origin xyz="0.117803138552674 0.0228565208888156 0.00500000000000111" rpy="3.14159265358979 0 3.14159265358979"/>
    <parent link="left_link1"/><child link="left_link4"/>
    <axis xyz="0 0 1"/>
    <limit lower="-1.5708" upper="1.5708" effort="80" velocity="3.0"/>
  </joint>

  <link name="left_link5">
    <inertial><origin xyz="0.0589 0.01143 0" rpy="0 0 0"/><mass value="0.006154"/>
      <inertia ixx="3.585E-07" ixy="-1.513E-06" ixz="0" iyy="7.863E-06" iyz="0" izz="8.195E-06"/></inertial>
    <visual><origin xyz="0 0 0" rpy="0 0 0"/><geometry><mesh filename="package://audix/meshes/left_link5.STL"/></geometry><material name=""><color rgba="0.792 0.820 0.933 1"/></material></visual>
    <collision><origin xyz="0.059 0.011 0.0" rpy="0 0 0"/><geometry><box size="0.12 0.015 0.012"/></geometry></collision>
  </link>
  <joint name="left_joint5" type="revolute">
    <origin xyz="0.11780313855294 0.0228565208874148 0.00499999999999923" rpy="3.14159265358979 0 3.14159265358979"/>
    <parent link="left_link4"/><child link="left_link5"/>
    <axis xyz="0 0 -1"/>
    <limit lower="-1.5708" upper="1.5708" effort="80" velocity="3.0"/>
  </joint>

  <!-- Camera -->
  <link name="camera_link">
    <inertial>
      <origin xyz="-0.0682 0.02157 -0.04296" rpy="0 0 0"/>
      <mass value="0.354470"/>
      <inertia ixx="0.000341" ixy="5.382E-05" ixz="1.850E-08"
               iyy="0.000709" iyz="-3.643E-09" izz="0.000434"/>
    </inertial>
    <visual><origin xyz="0 0 0" rpy="0 0 0"/><geometry><mesh filename="package://audix/meshes/camera_link.STL"/></geometry><material name=""><color rgba="0.792 0.820 0.933 1"/></material></visual>
    <collision><origin xyz="-0.068 0.022 -0.043" rpy="0 0 0"/><geometry><box size="0.15 0.12 0.10"/></geometry></collision>
  </link>
  <joint name="camera_joint" type="revolute">
    <origin xyz="0.11780313855266 0.0228565208888024 0.0850000000000067" rpy="0 0 0"/>
    <parent link="left_link5"/><child link="camera_link"/>
    <axis xyz="0 0 1"/>
    <limit lower="-1.5708" upper="1.5708" effort="10" velocity="2.0"/>
  </joint>

  <!-- Right link 2/3/6 (base-mounted scissor arms) -->
  <link name="right_link2">
    <inertial><origin xyz="0.0589 0.01143 0" rpy="0 0 0"/><mass value="0.006154"/>
      <inertia ixx="3.585E-07" ixy="-1.513E-06" ixz="0" iyy="7.863E-06" iyz="0" izz="8.195E-06"/></inertial>
    <visual><origin xyz="0 0 0" rpy="0 0 0"/><geometry><mesh filename="package://audix/meshes/right_link2.STL"/></geometry><material name=""><color rgba="0.792 0.820 0.933 1"/></material></visual>
    <collision><origin xyz="0.059 0.011 0.0" rpy="0 0 0"/><geometry><box size="0.12 0.015 0.012"/></geometry></collision>
  </link>
  <joint name="right_joint2" type="revolute">
    <origin xyz="0.0199999999999953 0.037499999999994 0.0424999999999847" rpy="1.5707963267949 0 0"/>
    <parent link="scissors_lift_base"/><child link="right_link2"/>
    <axis xyz="0 0 1"/>
    <limit lower="-1.5708" upper="1.5708" effort="80" velocity="3.0"/>
  </joint>

  <link name="right_link3">
    <inertial><origin xyz="0.0589 0.01143 0" rpy="0 0 0"/><mass value="0.006154"/>
      <inertia ixx="3.585E-07" ixy="-1.513E-06" ixz="0" iyy="7.863E-06" iyz="0" izz="8.195E-06"/></inertial>
    <visual><origin xyz="0 0 0" rpy="0 0 0"/><geometry><mesh filename="package://audix/meshes/right_link3.STL"/></geometry><material name=""><color rgba="0.792 0.820 0.933 1"/></material></visual>
    <collision><origin xyz="0.059 0.011 0.0" rpy="0 0 0"/><geometry><box size="0.12 0.015 0.012"/></geometry></collision>
  </link>
  <joint name="right_joint3" type="revolute">
    <origin xyz="0.117803138552934 0.0228565208874355 -0.00500000000000012" rpy="3.14159265358979 0 3.14159265358979"/>
    <parent link="right_link2"/><child link="right_link3"/>
    <axis xyz="0 0 -1"/>
    <limit lower="-1.5708" upper="1.5708" effort="80" velocity="3.0"/>
  </joint>

  <link name="right_link6">
    <inertial><origin xyz="0.0589 0.01143 0" rpy="0 0 0"/><mass value="0.006154"/>
      <inertia ixx="3.585E-07" ixy="-1.513E-06" ixz="0" iyy="7.863E-06" iyz="0" izz="8.195E-06"/></inertial>
    <visual><origin xyz="0 0 0" rpy="0 0 0"/><geometry><mesh filename="package://audix/meshes/right_link6.STL"/></geometry><material name=""><color rgba="0.792 0.820 0.933 1"/></material></visual>
    <collision><origin xyz="0.059 0.011 0.0" rpy="0 0 0"/><geometry><box size="0.12 0.015 0.012"/></geometry></collision>
  </link>
  <joint name="right_joint6" type="revolute">
    <origin xyz="0.11780313855268 0.0228565208887971 -0.00500000000000211" rpy="-3.14159265358979 0 -3.14159265358979"/>
    <parent link="right_link3"/><child link="right_link6"/>
    <axis xyz="0 0 -1"/>
    <limit lower="-1.5708" upper="1.5708" effort="80" velocity="3.0"/>
  </joint>

  <!-- Left link 2/3/6 -->
  <link name="left_link2">
    <inertial><origin xyz="0.0589 0.01143 0" rpy="0 0 0"/><mass value="0.006154"/>
      <inertia ixx="3.585E-07" ixy="-1.513E-06" ixz="0" iyy="7.863E-06" iyz="0" izz="8.195E-06"/></inertial>
    <visual><origin xyz="0 0 0" rpy="0 0 0"/><geometry><mesh filename="package://audix/meshes/left_link2.STL"/></geometry><material name=""><color rgba="0.792 0.820 0.933 1"/></material></visual>
    <collision><origin xyz="0.059 0.011 0.0" rpy="0 0 0"/><geometry><box size="0.12 0.015 0.012"/></geometry></collision>
  </link>
  <joint name="left_joint2" type="revolute">
    <origin xyz="0.0199999999999877 -0.037500000000009 0.0424999999999793" rpy="1.5707963267949 0 0"/>
    <parent link="scissors_lift_base"/><child link="left_link2"/>
    <axis xyz="0 0 1"/>
    <limit lower="-1.5708" upper="1.5708" effort="80" velocity="3.0"/>
  </joint>

  <link name="left_link3">
    <inertial><origin xyz="0.0589 0.01143 0" rpy="0 0 0"/><mass value="0.006154"/>
      <inertia ixx="3.585E-07" ixy="-1.513E-06" ixz="0" iyy="7.863E-06" iyz="0" izz="8.195E-06"/></inertial>
    <visual><origin xyz="0 0 0" rpy="0 0 0"/><geometry><mesh filename="package://audix/meshes/left_link3.STL"/></geometry><material name=""><color rgba="0.792 0.820 0.933 1"/></material></visual>
    <collision><origin xyz="0.059 0.011 0.0" rpy="0 0 0"/><geometry><box size="0.12 0.015 0.012"/></geometry></collision>
  </link>
  <joint name="left_joint3" type="revolute">
    <origin xyz="0.117803138552934 0.0228565208874119 0.00500000000000156" rpy="3.14159265358979 0 3.14159265358979"/>
    <parent link="left_link2"/><child link="left_link3"/>
    <axis xyz="0 0 -1"/>
    <limit lower="-1.5708" upper="1.5708" effort="80" velocity="3.0"/>
  </joint>

  <link name="left_link6">
    <inertial><origin xyz="0.0589 0.01143 0" rpy="0 0 0"/><mass value="0.006154"/>
      <inertia ixx="3.585E-07" ixy="-1.513E-06" ixz="0" iyy="7.863E-06" iyz="0" izz="8.195E-06"/></inertial>
    <visual><origin xyz="0 0 0" rpy="0 0 0"/><geometry><mesh filename="package://audix/meshes/left_link6.STL"/></geometry><material name=""><color rgba="0.792 0.820 0.933 1"/></material></visual>
    <collision><origin xyz="0.059 0.011 0.0" rpy="0 0 0"/><geometry><box size="0.12 0.015 0.012"/></geometry></collision>
  </link>
  <joint name="left_joint6" type="revolute">
    <origin xyz="0.117803138552671 0.0228565208888066 0.00500000000000234" rpy="-3.14159265358979 0 -3.14159265358979"/>
    <parent link="left_link3"/><child link="left_link6"/>
    <axis xyz="0 0 -1"/>
    <limit lower="-1.5708" upper="1.5708" effort="80" velocity="3.0"/>
  </joint>

  <!-- Top stud -->
  <link name="top_stud_link">
    <inertial><origin xyz="-7.501E-08 -7.194E-07 -1.618E-06" rpy="0 0 0"/><mass value="0.001371"/>
      <inertia ixx="1.363E-06" ixy="1.136E-11" ixz="-2.262E-13" iyy="2.721E-09" iyz="0" izz="1.363E-06"/></inertial>
    <visual><origin xyz="0 0 0" rpy="0 0 0"/><geometry><mesh filename="package://audix/meshes/top_stud_link.STL"/></geometry><material name=""><color rgba="0.776 0.757 0.737 1"/></material></visual>
    <collision><origin xyz="0 0 0" rpy="0 0 0"/><geometry><cylinder radius="0.004" length="0.015"/></geometry></collision>
  </link>
  <joint name="top_stud_joint" type="prismatic">
    <origin xyz="0.117801346067551 0.022856657474836 -0.0371507194079034" rpy="-1.5707963267949 0 1.5707963267949"/>
    <parent link="left_link6"/><child link="top_stud_link"/>
    <axis xyz="0 0 1"/>
    <limit lower="-0.05" upper="0.05" effort="150" velocity="0.15"/>
  </joint>

  <!-- ============================================================ -->
  <!-- SENSOR FRAMES                                                 -->
  <!-- ============================================================ -->

  <!-- IR Sensors (from user's updated URDF) -->
  <link name="ir_back_link"/>
  <joint name="ir_back_joint" type="fixed">
    <origin xyz="0.00389 -0.15402 0.01325" rpy="0 1.5707963267949 0"/>
    <parent link="base_link"/><child link="ir_back_link"/>
  </joint>

  <link name="ir_right_link"/>
  <joint name="ir_right_joint" type="fixed">
    <origin xyz="-0.15593 0.00425 0.01325" rpy="0 1.5707963267949 1.5707963267949"/>
    <parent link="base_link"/><child link="ir_right_link"/>
  </joint>

  <link name="ir_front_right_link"/>
  <joint name="ir_front_right_joint" type="fixed">
    <origin xyz="-0.33619 -0.02391 0.01325" rpy="0 1.5707963267949 2.3561944901923"/>
    <parent link="base_link"/><child link="ir_front_right_link"/>
  </joint>

  <link name="ir_front_link"/>
  <joint name="ir_front_joint" type="fixed">
    <origin xyz="-0.36061 -0.14597 0.01325" rpy="0 1.5707963267949 3.1415926535898"/>
    <parent link="base_link"/><child link="ir_front_link"/>
  </joint>

  <link name="ir_front_left_link"/>
  <joint name="ir_front_left_joint" type="fixed">
    <origin xyz="-0.34189 -0.27041 0.01325" rpy="0 1.5707963267949 -2.3561944901923"/>
    <parent link="base_link"/><child link="ir_front_left_link"/>
  </joint>

  <link name="ir_left_link"/>
  <joint name="ir_left_joint" type="fixed">
    <origin xyz="-0.16403 -0.30425 0.01325" rpy="0 1.5707963267949 -1.5707963267949"/>
    <parent link="base_link"/><child link="ir_left_link"/>
  </joint>

  <!-- Camera Optical Frame -->
  <link name="camera_optical_link"/>
  <joint name="camera_optical_joint" type="fixed">
    <origin xyz="-0.0285214690324131 0.0532714690323321 -0.0320399999999404" rpy="-1.5707963267949 0 -1.57079632679491"/>
    <parent link="camera_link"/><child link="camera_optical_link"/>
  </joint>

  <!-- IMU Frame -->
  <link name="imu_link"/>
  <joint name="imu_joint" type="fixed">
    <origin xyz="-0.15866 -0.15079 0.010" rpy="0 0 0"/>
    <parent link="base_link"/><child link="imu_link"/>
  </joint>

  <!-- ============================================================ -->
  <!-- ros2_control — wheels (velocity) + scissor joints (position) -->
  <!-- ============================================================ -->
  <ros2_control name="GazeboSystem" type="system">
    <hardware>
      <plugin>gz_ros2_control/GazeboSimSystem</plugin>
    </hardware>
    <!-- Wheels — velocity controlled -->
    <joint name="front_left_wheel_joint">
      <command_interface name="velocity"/>
      <state_interface name="velocity"/>
      <state_interface name="position"/>
    </joint>
    <joint name="front_right_wheel_joint">
      <command_interface name="velocity"/>
      <state_interface name="velocity"/>
      <state_interface name="position"/>
    </joint>
    <joint name="back_left_wheel_joint">
      <command_interface name="velocity"/>
      <state_interface name="velocity"/>
      <state_interface name="position"/>
    </joint>
    <joint name="back_right_wheel_joint">
      <command_interface name="velocity"/>
      <state_interface name="velocity"/>
      <state_interface name="position"/>
    </joint>
    <!-- Scissor lift — all position controlled -->
    <joint name="bottom_stud_joint">
      <command_interface name="position"/>
      <state_interface name="position"/>
      <state_interface name="velocity"/>
    </joint>
    <joint name="right_joint1"><command_interface name="position"/><state_interface name="position"/><state_interface name="velocity"/></joint>
    <joint name="right_joint2"><command_interface name="position"/><state_interface name="position"/><state_interface name="velocity"/></joint>
    <joint name="right_joint3"><command_interface name="position"/><state_interface name="position"/><state_interface name="velocity"/></joint>
    <joint name="right_joint4"><command_interface name="position"/><state_interface name="position"/><state_interface name="velocity"/></joint>
    <joint name="right_joint5"><command_interface name="position"/><state_interface name="position"/><state_interface name="velocity"/></joint>
    <joint name="right_joint6"><command_interface name="position"/><state_interface name="position"/><state_interface name="velocity"/></joint>
    <joint name="left_joint1"><command_interface name="position"/><state_interface name="position"/><state_interface name="velocity"/></joint>
    <joint name="left_joint2"><command_interface name="position"/><state_interface name="position"/><state_interface name="velocity"/></joint>
    <joint name="left_joint3"><command_interface name="position"/><state_interface name="position"/><state_interface name="velocity"/></joint>
    <joint name="left_joint4"><command_interface name="position"/><state_interface name="position"/><state_interface name="velocity"/></joint>
    <joint name="left_joint5"><command_interface name="position"/><state_interface name="position"/><state_interface name="velocity"/></joint>
    <joint name="left_joint6"><command_interface name="position"/><state_interface name="position"/><state_interface name="velocity"/></joint>
    <joint name="camera_joint"><command_interface name="position"/><state_interface name="position"/><state_interface name="velocity"/></joint>
    <joint name="top_stud_joint"><command_interface name="position"/><state_interface name="position"/><state_interface name="velocity"/></joint>
  </ros2_control>

  <!-- ============================================================ -->
  <!-- Gazebo plugins                                                -->
  <!-- ============================================================ -->
  <gazebo>
    <plugin filename="gz_ros2_control-system" name="gz_ros2_control::GazeboSimROS2ControlPlugin">
      <parameters>$(arg controllers_yaml)</parameters>
      <ros><remapping>~/robot_description:=robot_description</remapping></ros>
    </plugin>
  </gazebo>

  <!-- Wheel friction -->
  <gazebo reference="front_left_wheel_link"><mu1>1.0</mu1><mu2>1.0</mu2></gazebo>
  <gazebo reference="front_right_wheel_link"><mu1>1.0</mu1><mu2>1.0</mu2></gazebo>
  <gazebo reference="back_left_wheel_link"><mu1>1.0</mu1><mu2>1.0</mu2></gazebo>
  <gazebo reference="back_right_wheel_link"><mu1>1.0</mu1><mu2>1.0</mu2></gazebo>

  <!-- IMU sensor -->
  <gazebo reference="imu_link">
    <sensor name="imu_sensor" type="imu">
      <pose>0 0 0 0 0 0</pose>
      <always_on>true</always_on>
      <update_rate>100</update_rate>
      <topic>/imu</topic>
      <imu>
        <angular_velocity>
          <x><noise type="gaussian"><mean>0.0</mean><stddev>0.009</stddev></noise></x>
          <y><noise type="gaussian"><mean>0.0</mean><stddev>0.009</stddev></noise></y>
          <z><noise type="gaussian"><mean>0.0</mean><stddev>0.009</stddev></noise></z>
        </angular_velocity>
        <linear_acceleration>
          <x><noise type="gaussian"><mean>0.0</mean><stddev>0.021</stddev></noise></x>
          <y><noise type="gaussian"><mean>0.0</mean><stddev>0.021</stddev></noise></y>
          <z><noise type="gaussian"><mean>0.0</mean><stddev>0.021</stddev></noise></z>
        </linear_acceleration>
      </imu>
    </sensor>
  </gazebo>

  <!-- 6x IR sensors as gpu_lidar (35deg FOV, 0.30m range) -->
  <gazebo reference="ir_back_link">
    <sensor name="ir_back" type="gpu_lidar">
      <pose>0 0 0 0 -1.5707963267949 0</pose>
      <always_on>true</always_on><update_rate>10</update_rate><topic>/ir_back/scan</topic>
      <lidar><scan><horizontal><samples>10</samples><resolution>1</resolution><min_angle>-0.30543</min_angle><max_angle>0.30543</max_angle></horizontal><vertical><samples>1</samples><resolution>1</resolution><min_angle>0</min_angle><max_angle>0</max_angle></vertical></scan><range><min>0.05</min><max>0.30</max><resolution>0.01</resolution></range><noise><type>gaussian</type><mean>0.0</mean><stddev>0.005</stddev></noise></lidar>
      <visualize>true</visualize>
    </sensor>
  </gazebo>

  <gazebo reference="ir_right_link">
    <sensor name="ir_right" type="gpu_lidar">
      <pose>0 0 0 0 -1.5707963267949 0</pose>
      <always_on>true</always_on><update_rate>10</update_rate><topic>/ir_right/scan</topic>
      <lidar><scan><horizontal><samples>10</samples><resolution>1</resolution><min_angle>-0.30543</min_angle><max_angle>0.30543</max_angle></horizontal><vertical><samples>1</samples><resolution>1</resolution><min_angle>0</min_angle><max_angle>0</max_angle></vertical></scan><range><min>0.05</min><max>0.30</max><resolution>0.01</resolution></range><noise><type>gaussian</type><mean>0.0</mean><stddev>0.005</stddev></noise></lidar>
      <visualize>true</visualize>
    </sensor>
  </gazebo>

  <gazebo reference="ir_front_right_link">
    <sensor name="ir_front_right" type="gpu_lidar">
      <pose>0 0 0 0 -1.5707963267949 0</pose>
      <always_on>true</always_on><update_rate>10</update_rate><topic>/ir_front_right/scan</topic>
      <lidar><scan><horizontal><samples>10</samples><resolution>1</resolution><min_angle>-0.30543</min_angle><max_angle>0.30543</max_angle></horizontal><vertical><samples>1</samples><resolution>1</resolution><min_angle>0</min_angle><max_angle>0</max_angle></vertical></scan><range><min>0.05</min><max>0.30</max><resolution>0.01</resolution></range><noise><type>gaussian</type><mean>0.0</mean><stddev>0.005</stddev></noise></lidar>
      <visualize>true</visualize>
    </sensor>
  </gazebo>

  <gazebo reference="ir_front_link">
    <sensor name="ir_front" type="gpu_lidar">
      <pose>0 0 0 0 -1.5707963267949 0</pose>
      <always_on>true</always_on><update_rate>10</update_rate><topic>/ir_front/scan</topic>
      <lidar><scan><horizontal><samples>10</samples><resolution>1</resolution><min_angle>-0.30543</min_angle><max_angle>0.30543</max_angle></horizontal><vertical><samples>1</samples><resolution>1</resolution><min_angle>0</min_angle><max_angle>0</max_angle></vertical></scan><range><min>0.05</min><max>0.30</max><resolution>0.01</resolution></range><noise><type>gaussian</type><mean>0.0</mean><stddev>0.005</stddev></noise></lidar>
      <visualize>true</visualize>
    </sensor>
  </gazebo>

  <gazebo reference="ir_front_left_link">
    <sensor name="ir_front_left" type="gpu_lidar">
      <pose>0 0 0 0 -1.5707963267949 0</pose>
      <always_on>true</always_on><update_rate>10</update_rate><topic>/ir_front_left/scan</topic>
      <lidar><scan><horizontal><samples>10</samples><resolution>1</resolution><min_angle>-0.30543</min_angle><max_angle>0.30543</max_angle></horizontal><vertical><samples>1</samples><resolution>1</resolution><min_angle>0</min_angle><max_angle>0</max_angle></vertical></scan><range><min>0.05</min><max>0.30</max><resolution>0.01</resolution></range><noise><type>gaussian</type><mean>0.0</mean><stddev>0.005</stddev></noise></lidar>
      <visualize>true</visualize>
    </sensor>
  </gazebo>

  <gazebo reference="ir_left_link">
    <sensor name="ir_left" type="gpu_lidar">
      <pose>0 0 0 0 -1.5707963267949 0</pose>
      <always_on>true</always_on><update_rate>10</update_rate><topic>/ir_left/scan</topic>
      <lidar><scan><horizontal><samples>10</samples><resolution>1</resolution><min_angle>-0.30543</min_angle><max_angle>0.30543</max_angle></horizontal><vertical><samples>1</samples><resolution>1</resolution><min_angle>0</min_angle><max_angle>0</max_angle></vertical></scan><range><min>0.05</min><max>0.30</max><resolution>0.01</resolution></range><noise><type>gaussian</type><mean>0.0</mean><stddev>0.005</stddev></noise></lidar>
      <visualize>true</visualize>
    </sensor>
  </gazebo>

</robot>
